```python
try:
    print('try...')
    r = 10 / 0
    print('result:', r)
except ZeroDivisionError as e:
    print('except:', e)
finally:
    print('finally...')
print('END')
```


```python
try:
    print('try...')
    r = 10 / int('a')
    print('result:', r)
except ValueError as e:
    print('ValueError:', e)
except ZeroDivisionError as e:
    print('ZeroDivisionError:', e)
finally:
    print('finally...')
print('END')
```


此外，如果没有错误发生，可以在`except`语句块后面加一个`else`，当没有错误发生时，会自动执行`else`语句：

```python
try:
    print('try...')
    r = 10 / int('2')
    print('result:', r)
except ValueError as e:
    print('ValueError:', e)
except ZeroDivisionError as e:
    print('ZeroDivisionError:', e)
else:
    print('no error!')
finally:
    print('finally...')
print('END')
```

Python的错误其实也是class，所有的错误类型都继承自`BaseException`，所以在使用`except`时需要注意的是，它不但捕获该类型的错误，还把其子类也“一网打尽”。比如：

```python
try:
    foo()
except ValueError as e:
    print('ValueError')
except UnicodeError as e:
    print('UnicodeError')
```

第二个`except`永远也捕获不到`UnicodeError`，因为`UnicodeError`是`ValueError`的子类，如果有，也被第一个`except`给捕获了。

Python所有的错误都是从`BaseException`类派生的，常见的错误类型和继承关系看这里：

==使用`try...except`捕获错误还有一个巨大的好处，就是可以跨越多层调用，==比如函数`main()`调用`bar()`，`bar()`调用`foo()`，结果`foo()`出错了，这时，只要`main()`捕获到了，就可以处理：

也就是说，==不需要在每个可能出错的地方去捕获错误，只要在合适的层次去捕获错误就可以了==。这样一来，就大大减少了写`try...except...finally`的麻烦。

Python内置的`logging`模块可以非常容易地记录错误信息：

```python
import logging

def foo(s):
    return 10 / int(s)

def bar(s):
    return foo(s) * 2

def main():
    try:
        bar('0')
    except Exception as e:
        logging.exception(e)

main()
print('END')
```

因为错误是class，捕获一个错误就是捕获到该class的一个实例。因此，错误并不是凭空产生的，而是有意创建并抛出的。Python的内置函数会抛出很多类型的错误，我们自己编写的函数也可以抛出错误。

如果要抛出错误，首先根据需要，==可以定义一个错误的class，选择好继承关系，然后，用`raise`语句抛出一个错误的实例：==
```python
class FooError(ValueError):
    pass

def foo(s):
    n = int(s)
    if n==0:
        raise FooError('invalid value: %s' % s)
    return 10 / n

foo('0')
```

只有在必要的时候才定义我们自己的错误类型。如果可以选择Python已有的内置的错误类型（比如`ValueError`，`TypeError`），尽量使用Python内置的错误类型。

在`bar()`函数中，我们明明已经捕获了错误，但是，打印一个`ValueError!`后，又把错误通过`raise`语句抛出去了，这不有病么？

其实这种错误处理方式不但没病，而且相当常见。捕获错误目的只是记录一下，便于后续追踪。但是，由于当前函数不知道应该怎么处理该错误，所以，最恰当的方式是继续往上抛，让顶层调用者去处理。好比一个员工处理不了一个问题时，就把问题抛给他的老板，如果他的老板也处理不了，就一直往上抛，最终会抛给CEO去处理。

`raise`语句如果不带参数，就会把当前错误原样抛出。此外，在`except`中`raise`一个Error，还可以把一种类型的错误转化成另一种类型：

```python
try:
    10 / 0
except ZeroDivisionError:
    raise ValueError('input error!')
```